Workbook

Sheet Hướng dẫn
A1: Hướng dẫn dùng bản copy
A3: Không sửa sheet gốc | B3: File này được tạo từ bản export của Google Sheet gốc và không ghi đè dữ liệu gốc.
A4: Khi lấy hàng | B4: Nhập một dòng trong tab Nhập hàng, chọn Đối tác công nợ, nhập số lượng/đơn giá hoặc nhập trực tiếp Thành tiền.
A5: Khi thanh toán | B5: Nhập một dòng trong tab Thanh toán. Công nợ ở tab Công nợ đối tác sẽ tự giảm.
A6: Khi trả hàng | B6: Nhập một dòng trong tab Trả hàng. Công nợ đối tác cũng tự giảm theo giá trị hàng trả.
A7: Thêm đối tác mới | B7: Thêm tên vào tab Đối tác, rồi chọn tên đó ở Nhập hàng/Thanh toán/Trả hàng.
A8: Đơn khách | B8: Tab Đơn khách là bản sạch từ tab Đơn hàng đã bán để chuẩn bị import hoặc đối chiếu web.

Sheet Tổng quan
A1: Tổng quan công nợ và đơn khách
A3: Tổng giá trị hàng lấy | B3: ='Công nợ đối tác'!B13 -> 66445500
A4: Tổng đã thanh toán đối tác | B4: ='Công nợ đối tác'!C13 -> 45000000
A5: Tổng hàng trả lại | B5: ='Công nợ đối tác'!D13 -> 1500000
A6: Công nợ đối tác hiện tại | B6: ='Công nợ đối tác'!E13 -> 19945500
A7: Tổng tiền đơn khách | B7: =SUM('Đơn khách'!F:F) -> 34640000
A8: Đã thu từ khách | B8: =SUM('Đơn khách'!G:G) -> 26150000
A9: Khách còn nợ | B9: =SUM('Đơn khách'!H:H) -> 8490000
A12: Cách hiểu công nợ | B12: Công nợ đối tác = Giá trị hàng lấy - Đã thanh toán - Hàng trả lại. Số dương là Minh Hồng còn phải trả; số âm là đã chuyển dư/tạm ứng.

Sheet Công nợ đối tác
A1: Đối tác | B1: Giá trị hàng lấy | C1: Đã thanh toán | D1: Hàng trả lại | E1: Công nợ còn phải trả | F1: Trạng thái | G1: Ghi chú
A2: Long | B2: =SUMIFS('Nhập hàng'!$J:$J,'Nhập hàng'!$C:$C,A2) -> 66445500 | C2: =SUMIFS('Thanh toán'!$D:$D,'Thanh toán'!$C:$C,A2) -> 45000000 | D2: =SUMIFS('Trả hàng'!$H:$H,'Trả hàng'!$C:$C,A2) -> 1500000 | E2: =B2-C2-D2 -> 19945500 | F2: =IF(E2>0,"Còn phải trả đối tác",IF(E2<0,"Đã chuyển dư/tạm ứng","Đã cân bằng")) -> Còn phải trả đối tác
A3: Shopee | B3: =SUMIFS('Nhập hàng'!$J:$J,'Nhập hàng'!$C:$C,A3) -> 0 | C3: =SUMIFS('Thanh toán'!$D:$D,'Thanh toán'!$C:$C,A3) -> 0 | D3: =SUMIFS('Trả hàng'!$H:$H,'Trả hàng'!$C:$C,A3) -> 0 | E3: =B3-C3-D3 -> 0 | F3: =IF(E3>0,"Còn phải trả đối tác",IF(E3<0,"Đã chuyển dư/tạm ứng","Đã cân bằng")) -> Đã cân bằng
A4: Trần Viết Cường | B4: =SUMIFS('Nhập hàng'!$J:$J,'Nhập hàng'!$C:$C,A4) -> 0 | C4: =SUMIFS('Thanh toán'!$D:$D,'Thanh toán'!$C:$C,A4) -> 0 | D4: =SUMIFS('Trả hàng'!$H:$H,'Trả hàng'!$C:$C,A4) -> 0 | E4: =B4-C4-D4 -> 0 | F4: =IF(E4>0,"Còn phải trả đối tác",IF(E4<0,"Đã chuyển dư/tạm ứng","Đã cân bằng")) -> Đã cân bằng
A5: a Tâm | B5: =SUMIFS('Nhập hàng'!$J:$J,'Nhập hàng'!$C:$C,A5) -> 0 | C5: =SUMIFS('Thanh toán'!$D:$D,'Thanh toán'!$C:$C,A5) -> 0 | D5: =SUMIFS('Trả hàng'!$H:$H,'Trả hàng'!$C:$C,A5) -> 0 | E5: =B5-C5-D5 -> 0 | F5: =IF(E5>0,"Còn phải trả đối tác",IF(E5<0,"Đã chuyển dư/tạm ứng","Đã cân bằng")) -> Đã cân bằng
A6: Điện tử Lào Cai | B6: =SUMIFS('Nhập hàng'!$J:$J,'Nhập hàng'!$C:$C,A6) -> 0 | C6: =SUMIFS('Thanh toán'!$D:$D,'Thanh toán'!$C:$C,A6) -> 0 | D6: =SUMIFS('Trả hàng'!$H:$H,'Trả hàng'!$C:$C,A6) -> 0 | E6: =B6-C6-D6 -> 0 | F6: =IF(E6>0,"Còn phải trả đối tác",IF(E6<0,"Đã chuyển dư/tạm ứng","Đã cân bằng")) -> Đã cân bằng
A7: Dương Mạnh Ninh | B7: =SUMIFS('Nhập hàng'!$J:$J,'Nhập hàng'!$C:$C,A7) -> 0 | C7: =SUMIFS('Thanh toán'!$D:$D,'Thanh toán'!$C:$C,A7) -> 0 | D7: =SUMIFS('Trả hàng'!$H:$H,'Trả hàng'!$C:$C,A7) -> 0 | E7: =B7-C7-D7 -> 0 | F7: =IF(E7>0,"Còn phải trả đối tác",IF(E7<0,"Đã chuyển dư/tạm ứng","Đã cân bằng")) -> Đã cân bằng
A8: Nguyễn Thành | B8: =SUMIFS('Nhập hàng'!$J:$J,'Nhập hàng'!$C:$C,A8) -> 0 | C8: =SUMIFS('Thanh toán'!$D:$D,'Thanh toán'!$C:$C,A8) -> 0 | D8: =SUMIFS('Trả hàng'!$H:$H,'Trả hàng'!$C:$C,A8) -> 0 | E8: =B8-C8-D8 -> 0 | F8: =IF(E8>0,"Còn phải trả đối tác",IF(E8<0,"Đã chuyển dư/tạm ứng","Đã cân bằng")) -> Đã cân bằng
A9: Hiếu LK | B9: =SUMIFS('Nhập hàng'!$J:$J,'Nhập hàng'!$C:$C,A9) -> 0 | C9: =SUMIFS('Thanh toán'!$D:$D,'Thanh toán'!$C:$C,A9) -> 0 | D9: =SUMIFS('Trả hàng'!$H:$H,'Trả hàng'!$C:$C,A9) -> 0 | E9: =B9-C9-D9 -> 0 | F9: =IF(E9>0,"Còn phải trả đối tác",IF(E9<0,"Đã chuyển dư/tạm ứng","Đã cân bằng")) -> Đã cân bằng
A10: Tuấn Mạnh AZ | B10: =SUMIFS('Nhập hàng'!$J:$J,'Nhập hàng'!$C:$C,A10) -> 0 | C10: =SUMIFS('Thanh toán'!$D:$D,'Thanh toán'!$C:$C,A10) -> 0 | D10: =SUMIFS('Trả hàng'!$H:$H,'Trả hàng'!$C:$C,A10) -> 0 | E10: =B10-C10-D10 -> 0 | F10: =IF(E10>0,"Còn phải trả đối tác",IF(E10<0,"Đã chuyển dư/tạm ứng","Đã cân bằng")) -> Đã cân bằng
A11: Khác | B11: =SUMIFS('Nhập hàng'!$J:$J,'Nhập hàng'!$C:$C,A11) -> 0 | C11: =SUMIFS('Thanh toán'!$D:$D,'Thanh toán'!$C:$C,A11) -> 0 | D11: =SUMIFS('Trả hàng'!$H:$H,'Trả hàng'!$C:$C,A11) -> 0 | E11: =B11-C11-D11 -> 0 | F11: =IF(E11>0,"Còn phải trả đối tác",IF(E11<0,"Đã chuyển dư/tạm ứng","Đã cân bằng")) -> Đã cân bằng
A13: Tổng cộng | B13: =SUM(B2:B12) -> 66445500 | C13: =SUM(C2:C12) -> 45000000 | D13: =SUM(D2:D12) -> 1500000 | E13: =SUM(E2:E12) -> 19945500

Sheet Nhập hàng
A1: Mã nhập | B1: Ngày nhập | C1: Đối tác công nợ | D1: Người bán/nguồn gốc | E1: Tên hàng | F1: Loại | G1: Số lượng | H1: Đơn vị | I1: Đơn giá | J1: Thành tiền | K1: Đã nhận hàng | L1: Ghi chú | M1: Dòng gốc
A2: NH-0001 | C2: Long | D2: Shopee | E2: 40 Khay cân 21700 | F2: Vật tư/đồ nghề | G2: 40 | J2: 637700 | K2: Có | L2: SHOPEE (xem trong nhóm) | M2: Sheet1!A4:J4
A3: NH-0002 | C3: Long | D3: Shopee | E3: 50 Vôn kế bảng sạc đỏ + vàng | F3: Vật tư/đồ nghề | G3: 50 | J3: 595300 | K3: Có | L3: SHOPEE (xem trong nhóm) | M3: Sheet1!A5:J5
A4: NH-0003 | C4: Long | E4: Khay Cân bằng Hoàng Long | F4: Vật tư/đồ nghề | J4: 5090000 | K4: Có | L4: Hóa đơn trong nhóm | M4: Sheet1!A6:J6
A5: NH-0004 | C5: Long | E5: Công tắc Led (2 đợt) | F5: Vật tư/đồ nghề | G5: 16 | I5: 20000 | J5: 320000 | K5: Có | L5: Hóa đơn trong nhóm | M5: Sheet1!A7:J7
A6: NH-0005 | C6: Long | E6: Cắt ván + dán chỉ (chỗ Hựu) | F6: Vật tư/đồ nghề | J6: 300000 | K6: Có | L6: Hóa đơn trong nhóm | M6: Sheet1!A8:J8
A7: NH-0006 | C7: Long | E7: Nguồn 5V cũ | F7: Vật tư/đồ nghề | G7: 2 | I7: 80000 | J7: 160000 | K7: Có | L7: Hóa đơn trong nhóm | M7: Sheet1!A9:J9
A8: NH-0007 | C8: Long | E8: Nguồn 5V 60A new tốt | F8: Vật tư/đồ nghề | G8: 2 | I8: 235000 | J8: 470000 | K8: Có | L8: Hóa đơn trong nhóm | M8: Sheet1!A10:J10
A9: NH-0008 | C9: Long | E9: Linh kiện - Vật tư nhập về làm | F9: Vật tư/đồ nghề | J9: 3352000 | K9: Có | L9: Hóa đơn trong nhóm (ngày 4/9) | M9: Sheet1!A11:J11
A10: NH-0009 | C10: Long | D10: Trần Viết Cường | E10: Máy test nội trở + đế + que đo | F10: Vật tư/đồ nghề | J10: 800000 | K10: Có | L10: Hóa đơn trong nhóm | M10: Sheet1!A12:J12
A11: NH-0010 | C11: Long | D11: a Tâm | E11: Máy hàn cell pin | F11: Vật tư/đồ nghề | G11: 1 | I11: 1 | J11: 8500000 | K11: Có | L11: Đã tạm ứng 7,000,000 | M11: Sheet1!A13:J13
A12: NH-0011 | C12: Long | D12: a Tâm | E12: Máy gọt cell pin | F12: Vật tư/đồ nghề | G12: 1 | J12: 2200000 | K12: Có | M12: Sheet1!A14:J14
A13: NH-0012 | C13: Long | D13: Điện tử Lào Cai | E13: Bộ test công suất + chống chập | F13: Vật tư/đồ nghề | G13: 1 | J13: 500000 | K13: Có | M13: Sheet1!A15:J15
A14: NH-0013 | C14: Long | D14: Dương Mạnh Ninh | E14: Máy cấp nguồn 120V 25A | F14: Vật tư/đồ nghề | G14: 1 | J14: 2800000 | K14: Có | M14: Sheet1!A16:J16
A15: NH-0014 | C15: Long | D15: Nguyễn Thành | E15: Bảng sạc pin | F15: Vật tư/đồ nghề | G15: 1 | J15: 3200000 | K15: Có | L15: combo 5 bảng+tiền tk+VAT+ ship | M15: Sheet1!A17:J17
A16: NH-0015 | C16: Long | D16: Shopee | E16: Mạch test dung lượng + trở sứ | F16: Vật tư/đồ nghề | G16: 25 | J16: 812500 | K16: Có | L16: SHOPEE (xem trong nhóm) | M16: Sheet1!A18:J18
A17: NH-0016 | C17: Long | D17: Shopee | E17: Mạch test dung lượng + trở sứ | F17: Vật tư/đồ nghề | G17: 20 | J17: 653000 | K17: Có | L17: SHOPEE (xem trong nhóm) | M17: Sheet1!A19:J19
A18: NH-0017 | C18: Long | E18: Máy mài MKT TQ | F18: Vật tư/đồ nghề | G18: 1 | J18: 350000 | K18: Có | L18: xe Thanh đem về | M18: Sheet1!A20:J20
A19: NH-0018 | C19: Long | E19: Khoan 3CN starker 10mm đỏ | F19: Vật tư/đồ nghề | G19: 1 | J19: 260000 | K19: Có | L19: xe Thanh đem về | M19: Sheet1!A21:J21
A20: NH-0019 | C20: Long | E20: Bulong mkt TQ xám | F20: Vật tư/đồ nghề | G20: 1 | J20: 240000 | K20: Có | L20: xe Thanh đem về | M20: Sheet1!A22:J22
A21: NH-0020 | C21: Long | E21: Vít 173 tq xanh | F21: Vật tư/đồ nghề | G21: 1 | J21: 420000 | K21: Có | L21: xe Thanh đem về | M21: Sheet1!A23:J23
A22: NH-0021 | C22: Long | E22: Khoan 13mm YMS xanh | F22: Vật tư/đồ nghề | G22: 1 | J22: 800000 | K22: Có | L22: xe Thanh đem về | M22: Sheet1!A24:J24
A23: NH-0022 | C23: Long | E23: Đèn led nhỏ | F23: Vật tư/đồ nghề | G23: 1 | J23: 100000 | K23: Có | L23: xe Thanh đem về | M23: Sheet1!A25:J25
A24: NH-0023 | C24: Long | E24: Quạt lồg sắt | F24: Vật tư/đồ nghề | G24: 1 | J24: 115000 | K24: Có | L24: xe Thanh đem về | M24: Sheet1!A26:J26
A25: NH-0024 | C25: Long | E25: Kích điện từ pin lên 220v | F25: Vật tư/đồ nghề | G25: 1 | J25: 250000 | K25: Có | L25: xe Thanh đem về | M25: Sheet1!A27:J27
A26: NH-0025 | C26: Long | D26: Hiếu LK | E26: Thiếc hàng nhật 800g 0.8mm | F26: Vật tư/đồ nghề | G26: 1 | I26: 580000 | J26: 580000 | K26: Có | L26: xe Thanh đem về | M26: Sheet1!A28:J28
A27: NH-0026 | C27: Long | D27: Tuấn Mạnh AZ | E27: Bộ hộp pin xe điện (có khung+kẽm) | F27: Vật tư/đồ nghề | G27: 1 | J27: 160000 | K27: Có | L27: gửi xe Thanh chuyển xe bà Hà | M27: Sheet1!A29:J29
A28: NH-0027 | C28: Long | E28: Mạch pin 13/14s 40A | F28: Vật tư/đồ nghề | G28: 1 | J28: 160000 | K28: Có | L28: gửi xe Thanh chuyển xe bà Hà | M28: Sheet1!A30:J30
A29: NH-0028 | C29: Long | E29: Sạc 2s2A rẻ | F29: Vật tư/đồ nghề | G29: 2 | I29: 30000 | J29: 60000 | K29: Có | L29: gửi xe Thanh chuyển xe bà Hà | M29: Sheet1!A31:J31
A30: NH-0029 | C30: Long | E30: sạc 3s2A rẻ | F30: Vật tư/đồ nghề | G30: 2 | I30: 30000 | J30: 60000 | K30: Có | L30: gửi xe Thanh chuyển xe bà Hà | M30: Sheet1!A32:J32
A31: NH-0030 | C31: Long | E31: Sạc 3s2A thường | F31: Vật tư/đồ nghề | G31: 2 | I31: 55000 | J31: 110000 | K31: Có | L31: gửi xe Thanh chuyển xe bà Hà | M31: Sheet1!A33:J33
A32: NH-0031 | C32: Long | E32: Sạc 4s2A thường | F32: Vật tư/đồ nghề | G32: 2 | I32: 55000 | J32: 110000 | K32: Có | L32: gửi xe Thanh chuyển xe bà Hà | M32: Sheet1!A34:J34
A33: NH-0032 | C33: Long | E33: Sạc 5s2A rẻ | F33: Vật tư/đồ nghề | G33: 2 | I33: 30000 | J33: 60000 | K33: Có | L33: gửi xe Thanh chuyển xe bà Hà | M33: Sheet1!A35:J35
A34: NH-0033 | C34: Long | E34: Sạc 5s2A thường | F34: Vật tư/đồ nghề | G34: 2 | I34: 55000 | J34: 110000 | K34: Có | L34: gửi xe Thanh chuyển xe bà Hà | M34: Sheet1!A36:J36
A35: NH-0034 | C35: Long | E35: Sạc 5s3A có quạt | F35: Vật tư/đồ nghề | G35: 2 | I35: 110000 | J35: 220000 | K35: Có | L35: gửi xe Thanh chuyển xe bà Hà | M35: Sheet1!A37:J37
A36: NH-0035 | C36: Long | E36: Jack Xt60 | F36: Vật tư/đồ nghề | G36: 4 | I36: 3500 | J36: 14000 | K36: Có | L36: gửi xe Thanh chuyển xe bà Hà | M36: Sheet1!A38:J38
A37: NH-0036 | C37: Long | E37: Đèn NLMT BC 200w | F37: Vật tư/đồ nghề | G37: 1 | J37: 700000 | K37: Có | L37: gửi xe Thanh chuyển xe bà Hà | M37: Sheet1!A39:J39
A38: NH-0037 | C38: Long | E38: Đèn NLMT pha 300w | F38: Vật tư/đồ nghề | G38: 1 | J38: 950000 | K38: Có | L38: gửi xe Thanh chuyển xe bà Hà | M38: Sheet1!A40:J40
A39: NH-0038 | C39: Long | E39: Đèn NLMT mắt ngọc 300W | F39: Vật tư/đồ nghề | G39: 1 | J39: 950000 | K39: Có | L39: gửi xe Thanh chuyển xe bà Hà | M39: Sheet1!A41:J41
A40: NH-0039 | C40: Long | E40: dây AWG 12 | F40: Vật tư/đồ nghề | G40: 4 | K40: Có | L40: gửi xe Thanh chuyển xe bà Hà | M40: Sheet1!A42:J42
...

Sheet Thanh toán
A1: Mã thanh toán | B1: Ngày | C1: Đối tác | D1: Số tiền | E1: Phương thức | F1: Ghi chú
A2: TT-0001 | B2: 2/3/2026 | C2: Long | D2: 45000000 | E2: Chuyển khoản | F2: Từ đầu đến ngày 2/3/2026 tc ck cho long là 45tr
A3: TT-0002 | C3: Long
A4: TT-0003 | C4: Long
A5: TT-0004 | C5: Long
A6: TT-0005 | C6: Long
A7: TT-0006 | C7: Long
A8: TT-0007 | C8: Long
A9: TT-0008 | C9: Long
A10: TT-0009 | C10: Long
A11: TT-0010 | C11: Long
A12: TT-0011 | C12: Long
A13: TT-0012 | C13: Long
A14: TT-0013 | C14: Long
... A79: TT-0078 | C79: Long

Sheet Trả hàng
A1: Mã trả | B1: Ngày | C1: Đối tác | D1: Tên hàng | E1: Loại | F1: Số lượng | G1: Đơn giá | H1: Thành tiền | I1: Lý do/Ghi chú | J1: Dòng gốc
A2: TR-0001 | C2: Long | D2: A123 | F2: 50 | H2: 1150000 | I2: Nhập từ tab Đơn trả lại | J2: Đơn trả lại!A4:E4
A3: TR-0002 | C3: Long | D3: MÁY MÀI MKT TQ | F3: 1 | H3: 350000 | I3: Nhập từ tab Đơn trả lại | J3: Đơn trả lại!A5:E5
A4: TR-0003 | C4: Long | D4: PIN21700 | F4: 5 | I4: Nhập từ tab Đơn trả lại | J4: Đơn trả lại!A6:E6
A5: TR-0004 | C5: Long | D5: FIN18600 | F5: 6 | I5: Nhập từ tab Đơn trả lại | J5: Đơn trả lại!A7:E7
A6: TR-0005 | C6: Long | H6: =IF(OR(F6="",G6=""),"",F6*G6)
A7: TR-0006 | C7: Long | H7: =IF(OR(F7="",G7=""),"",F7*G7)
A8: TR-0007 | C8: Long | H8: =IF(OR(F8="",G8=""),"",F8*G8)
A9: TR-0008 | C9: Long | H9: =IF(OR(F9="",G9=""),"",F9*G9)
A10: TR-0009 | C10: Long | H10: =IF(OR(F10="",G10=""),"",F10*G10)
A11: TR-0010 | C11: Long | H11: =IF(OR(F11="",G11=""),"",F11*G11)
A12: TR-0011 | C12: Long | H12: =IF(OR(F12="",G12=""),"",F12*G12)
A13: TR-0012 | C13: Long | H13: =IF(OR(F13="",G13=""),"",F13*G13)
A14: TR-0013 | C14: Long | H14: =IF(OR(F14="",G14=""),"",F14*G14)
A15: TR-0014 | C15: Long | H15: =IF(OR(F15="",G15=""),"",F15*G15)
A16: TR-0015 | C16: Long | H16: =IF(OR(F16="",G16=""),"",F16*G16)
A17: TR-0016 | C17: Long | H17: =IF(OR(F17="",G17=""),"",F17*G17)
... A79: TR-0078 | C79: Long | H79: =IF(OR(F79="",G79=""),"",F79*G79)

Sheet Đơn khách
A1: Mã đơn | B1: Ngày mua | C1: Tên khách | D1: Số điện thoại | E1: Sản phẩm | F1: Tổng tiền | G1: Đã thu | H1: Còn nợ | I1: Ghi chú | J1: Dòng gốc
A2: DH-0001 | C2: TÂM LÊ | D2: 0935694536 | E2: 1FIN 12AH | F2: 1200000 | G2: 1200000 | H2: =MAX(F2-G2,0) -> 0 | J2: Đơn hàng đã bán!A4:I4
A3: DH-0002 | C3: KHOÁ NGUYỄN | D3: 0983926939 | E3: 1SAC1FIN7,5AH | F3: 950000 | G3: 950000 | H3: =MAX(F3-G3,0) -> 0 | I3: Mạch+đóng | J3: Đơn hàng đã bán!A5:I5
A4: DH-0003 | C4: HUỲNH KIỀU | D4: 0377732140 | E4: 1 ĐÈN NL 300W | F4: 1200000 | G4: 1200000 | H4: =MAX(F4-G4,0) -> 0 | J4: Đơn hàng đã bán!A6:I6
A5: DH-0004 | C5: NGUYỄN PHƯỚC THIỆN | D5: 0364909695 | E5: 1 SẠC DỰ PHÒNG 4CELL | F5: 550000 | G5: 550000 | H5: =MAX(F5-G5,0) -> 0 | J5: Đơn hàng đã bán!A7:I7
A6: DH-0005 | C6: HÀ LÊ | D6: 0987475125 | E6: 1BINH XE MÁY | F6: 600000 | G6: 600000 | H6: =MAX(F6-G6,0) -> 0 | J6: Đơn hàng đã bán!A8:I8
A7: DH-0006 | C7: Bình lâm Tâm | D7: 0972947410 | E7: Bình 30a | H7: =MAX(F7-G7,0) -> 0 | J7: Đơn hàng đã bán!A9:I9
A8: DH-0007 | C8: Vĩnh bộ đội | E8: Bình 45A | F8: 2300000 | G8: 1700000 | H8: =MAX(F8-G8,0) -> 600000 | J8: Đơn hàng đã bán!A10:I10
A9: DH-0008 | C9: Vương | E9: Pin 15cell | F9: 700000 | G9: 700000 | H9: =MAX(F9-G9,0) -> 0 | J9: Đơn hàng đã bán!A11:I11
A10: DH-0009 | C10: Sang | E10: Pin15cell-sạc-đèn | F10: 1000000 | G10: 1000000 | H10: =MAX(F10-G10,0) -> 0 | J10: Đơn hàng đã bán!A12:I12
A11: DH-0010 | C11: Liên cơ khí | E11: Đèn | F11: 250000 | G11: 250000 | H11: =MAX(F11-G11,0) -> 0 | J11: Đơn hàng đã bán!A13:I13
A12: DH-0011 | C12: Anh Hiệp | E12: Camera -pin5cell-đèn,sạc | F12: 650000 | G12: 650000 | H12: =MAX(F12-G12,0) -> 0 | J12: Đơn hàng đã bán!A14:I14
A13: DH-0012 | C13: Vĩnh bộ đội | E13: Bình 45ah-pin15cell-máy vít -sạc | F13: 3830000 | G13: 1600000 | H13: =MAX(F13-G13,0) -> 2230000 | J13: Đơn hàng đã bán!A15:I15
A14: DH-0013 | B14: 2026-01-12 00:00:00 | C14: Ut chup,0375064153/12/1/2026 | D14: 0375064153 | E14: Bình 45ah | F14: 2250000 | G14: 2250000 | H14: =MAX(F14-G14,0) -> 0 | I14: 375064152 | J14: Đơn hàng đã bán!A16:I16
A15: DH-0014 | B15: 2026-01-17 00:00:00 | C15: Bi trương | E15: Sạc tốt 5a | F15: 150000 | G15: 150000 | H15: =MAX(F15-G15,0) -> 0 | J15: Đơn hàng đã bán!A17:I17
A16: DH-0015 | B16: 2026-01-23 00:00:00 | C16: Phế liệu qs | E16: Pin15cell,máy bu lông | F16: 1500000 | G16: 1500000 | H16: =MAX(F16-G16,0) -> 0 | J16: Đơn hàng đã bán!A18:I18
A17: DH-0016 | B17: 37/1/2026 | C17: Phế liệu qs | E17: Pin 15cell1máy cắt,sạc | F17: 1300000 | G17: 1300000 | H17: =MAX(F17-G17,0) -> 0 | J17: Đơn hàng đã bán!A19:I19
A18: DH-0017 | B18: 28/012026 | C18: Tiên đoan | E18: Pin10-15cell,sạc | F18: 1350000 | G18: 1350000 | H18: =MAX(F18-G18,0) -> 0 | J18: Đơn hàng đã bán!A20:I20
A19: DH-0018 | B19: 2026-01-26 00:00:00 | C19: Khoá | E19: Sạc dự phòng | F19: 600000 | H19: =MAX(F19-G19,0) -> 600000 | J19: Đơn hàng đã bán!A21:I21
A20: DH-0019 | B20: 2026-03-03 00:00:00 | C20: Phế liệu qs | E20: Pin15cell,1 máy buloong | F20: 1200000 | G20: 1200000 | H20: =MAX(F20-G20,0) -> 0 | J20: Đơn hàng đã bán!A22:I22
A21: DH-0020 | B21: 2026-03-07 00:00:00 | C21: Mẹ Thêu QM | E21: Đèn NL đĩa bay | F21: 1500000 | G21: 1500000 | H21: =MAX(F21-G21,0) -> 0 | J21: Đơn hàng đã bán!A23:I23
A22: DH-0021 | B22: 2026-03-20 00:00:00 | C22: Khoá | E22: Thay mạch 4s | F22: 80000 | H22: =MAX(F22-G22,0) -> 80000 | J22: Đơn hàng đã bán!A24:I24
A23: DH-0022 | B23: 2026-03-23 00:00:00 | C23: Khoá | E23: 2 pin 15cell+1 sạch nhanh | F23: 1650000 | H23: =MAX(F23-G23,0) -> 1650000 | J23: Đơn hàng đã bán!A25:I25
A24: DH-0023 | B24: 2026-04-02 00:00:00 | C24: Long rèn | E24: Pin áo | F24: 550000 | G24: 550000 | H24: =MAX(F24-G24,0) -> 0 | J24: Đơn hàng đã bán!A26:I26
A25: DH-0024 | B25: 2026-04-04 00:00:00 | C25: Quốc dinh | D25: 0869029139 | E25: Pin áo,sạc | F25: 700000 | G25: 700000 | H25: =MAX(F25-G25,0) -> 0 | J25: Đơn hàng đã bán!A27:I27
A26: DH-0025 | B26: 2026-04-07 00:00:00 | C26: Đội 6 thôn 2 | E26: Đèn năng lượng | F26: 1300000 | G26: 1300000 | H26: =MAX(F26-G26,0) -> 0 | J26: Đơn hàng đã bán!A28:I28
A27: DH-0026 | B27: 2026-04-10 00:00:00 | C27: Thủy hoa t4 | E27: Pin áo 6cell217 | F27: 600000 | H27: =MAX(F27-G27,0) -> 600000 | J27: Đơn hàng đã bán!A29:I29
A28: DH-0027 | B28: 2026-04-09 00:00:00 | C28: Vợ thày đ15 | D28: 0397504447 | E28: Đèn NL,mã | F28: 1250000 | G28: 1250000 | H28: =MAX(F28-G28,0) -> 0 | J28: Đơn hàng đã bán!A30:I30
A29: DH-0028 | B29: 2026-04-18 00:00:00 | C29: Khoá | E29: Sạc 16,8v | F29: 70000 | H29: =MAX(F29-G29,0) -> 70000 | J29: Đơn hàng đã bán!A31:I31
A30: DH-0029 | B30: 2026-04-18 00:00:00 | C30: Quốc đ15 | E30: Pin áo điều hòa | F30: 470000 | G30: 470000 | H30: =MAX(F30-G30,0) -> 0 | J30: Đơn hàng đã bán!A32:I32
A31: DH-0030 | B31: 2026-04-20 00:00:00 | C31: Vinh bé sâm | E31: Pin áo điều hòa | F31: 600000 | G31: 600000 | H31: =MAX(F31-G31,0) -> 0 | J31: Đơn hàng đã bán!A33:I33
A32: DH-0031 | B32: 2026-04-22 00:00:00 | C32: Kha đ9 | E32: Pin áo điều hòa | F32: 480000 | G32: 480000 | H32: =MAX(F32-G32,0) -> 0 | J32: Đơn hàng đã bán!A34:I34
A33: DH-0032 | B33: 2026-04-24 00:00:00 | C33: Ngọc t1 | E33: Pin áo điều hoà | F33: 600000 | H33: =MAX(F33-G33,0) -> 600000 | J33: Đơn hàng đã bán!A35:I35
A34: DH-0033 | B34: 2026-05-04 00:00:00 | C34: Lê Tâm | E34: Pin 20cell | F34: 1150000 | G34: 1150000 | H34: =MAX(F34-G34,0) -> 0 | J34: Đơn hàng đã bán!A36:I36
A35: DH-0034 | B35: 2026-05-05 00:00:00 | C35: Nguyễn phước Thiện | E35: Bình 12v30ah+quạt 12v | F35: 2060000 | H35: =MAX(F35-G35,0) -> 2060000 | J35: Đơn hàng đã bán!A37:I37
A36: DH-0035 | C36: Tuấn công an | E36: 1pin 15cell1 xạc | H36: =MAX(F36-G36,0) -> 0 | J36: Đơn hàng đã bán!A38:I38
A37: DH-0036 | C37: Chính xe | E37: 1 pin 15cell | H37: =MAX(F37-G37,0) -> 0 | J37: Đơn hàng đã bán!A39:I39
A38: DH-0037 | C38: Ánh đội 15 | E38: 1 pin 16v | H38: =MAX(F38-G38,0) -> 0 | J38: Đơn hàng đã bán!A40:I40
A39: DH-0038 | H39: =MAX(F39-G39,0) -> 0
A40: DH-0039 | H40: =MAX(F40-G40,0) -> 0
...

Sheet Đối tác
A1: Tên đối tác | B1: Vai trò | C1: Số điện thoại | D1: Trạng thái/Ghi chú
A2: Long | B2: Đối tác công nợ chính hiện tại | D2: Đang theo dõi
A3: Shopee | B3: Nhà cung cấp/nguồn bán gốc từ sheet cũ | D3: Tùy dùng
A4: Trần Viết Cường | B4: Nhà cung cấp/nguồn bán gốc từ sheet cũ | D4: Tùy dùng
A5: a Tâm | B5: Nhà cung cấp/nguồn bán gốc từ sheet cũ | D5: Tùy dùng
A6: Điện tử Lào Cai | B6: Nhà cung cấp/nguồn bán gốc từ sheet cũ | D6: Tùy dùng
A7: Dương Mạnh Ninh | B7: Nhà cung cấp/nguồn bán gốc từ sheet cũ | D7: Tùy dùng
A8: Nguyễn Thành | B8: Nhà cung cấp/nguồn bán gốc từ sheet cũ | D8: Tùy dùng
A9: Hiếu LK | B9: Nhà cung cấp/nguồn bán gốc từ sheet cũ | D9: Tùy dùng
A10: Tuấn Mạnh AZ | B10: Nhà cung cấp/nguồn bán gốc từ sheet cũ | D10: Tùy dùng
A11: Khác | B11: Dùng tạm khi chưa biết tên đối tác | D11: Tùy dùng

Sheet Cảnh báo dữ liệu
A1: Mức | B1: Vấn đề | C1: Cách xử lý đề xuất
A2: Cần xác nhận | B2: Tab Sheet1 có ô tổng cũ chỉ cộng một vùng cố định (G4:G41), trong khi file còn các dòng vật tư phía dưới. | C2: Dùng tab Nhập hàng trong bản copy này để tổng công nợ cộng toàn bộ dòng đã chuẩn hóa.
A3: Cần xác nhận | B3: Tab Tiền chuyển cho long có chữ nhắc tới 50tr nhưng ô số tiền đọc được là 45.000.000. | C3: Hỏi Minh Hồng/anh Long chốt đúng tổng đã chuyển. Nếu đúng 50tr, sửa số ở tab Thanh toán.
A4: Cần xác nhận | B4: Bản copy đang gán mặc định các dòng nhập hàng cũ vào công nợ Long vì tab thanh toán hiện chỉ theo Long. | C4: Nếu dòng nào là mua trực tiếp từ đối tác khác, đổi cột Đối tác công nợ ở tab Nhập hàng sang đúng tên đối tác.
A5: Dữ liệu cũ | B5: Nhiều dòng nhập hàng thiếu ngày, đơn vị, đơn giá hoặc người bán gốc. | C5: Từ nay nhập theo tab Nhập hàng để công thức dễ kiểm tra.
A6: Dữ liệu cũ | B6: Tab Đơn hàng đã bán có số điện thoại/ngày mua/chú thích nằm ở nhiều cột khác nhau. | C6: Rà soát tab Đơn khách trước khi import lên web.
A7: Cần xác nhận | B7: Tổng tiền đơn khách 34.640.000 trừ đã thu 26.150.000 bằng 8.490.000, nhưng ô nợ còn cũ đang là 7.890.000. | C7: Rà soát các dòng còn nợ trong tab Đơn khách; bản copy tính lại còn nợ theo từng dòng bằng Tổng tiền - Đã thu.

Sheet Sheet1
C1: THỐNG KÊ THU CHI VẬT TƯ- DỤNG CỤ - ĐỒ NGHỀ | E1: @ | J1: HỒNG CHUYỂN KHOẢN
A2: Ngày/tháng/năm | B2: TÊN | C2: SL | D2: ĐƠN GIÁ | G2: THÀNH TIỀN | H2: GHI CHÚ | I2: Người bán | J2: TỪ NGÀY RA ĐẾN 24/09/2025
J3: TỔNG CỘNG.43.000.000
A4: 1 | B4: 40 Khay cân 21700 | C4: 40 | G4: 637700 | H4: SHOPEE (xem trong nhóm) | J4: 2/3/2026.ck 2000000
A5: 2 | B5: 50 Vôn kế bảng sạc đỏ + vàng | C5: 50 | G5: 595300 | H5: SHOPEE (xem trong nhóm)
A6: 3 | B6: Khay Cân bằng Hoàng Long | G6: 5090000 | H6: Hóa đơn trong nhóm
A7: 4 | B7: Công tắc Led (2 đợt) | C7: 16 | D7: 20000 | G7: 320000 | H7: Hóa đơn trong nhóm
A8: 5 | B8: Cắt ván + dán chỉ (chỗ Hựu) | G8: 300000 | H8: Hóa đơn trong nhóm
A9: 6 | B9: Nguồn 5V cũ | C9: 2 | D9: 80000 | G9: 160000 | H9: Hóa đơn trong nhóm
A10: 7 | B10: Nguồn 5V 60A new tốt | C10: 2 | D10: 235000 | G10: 470000 | H10: Hóa đơn trong nhóm
A11: 8 | B11: Linh kiện - Vật tư nhập về làm | G11: 3352000 | H11: Hóa đơn trong nhóm (ngày 4/9)
A12: 9 | B12: Máy test nội trở + đế + que đo | G12: 800000 | H12: Hóa đơn trong nhóm | I12: Trần Viết Cường
A13: 10 | B13: Máy hàn cell pin | C13: 1 | D13: 1 | G13: 8500000 | H13: Đã tạm ứng 7,000,000 | I13: a Tâm
A14: 11 | B14: Máy gọt cell pin | C14: 1 | G14: 2200000 | I14: a Tâm
A15: 12 | B15: Bộ test công suất + chống chập | C15: 1 | G15: 500000 | I15: Điện tử Lào Cai
A16: 13 | B16: Máy cấp nguồn 120V 25A | C16: 1 | G16: 2800000 | I16: Dương Mạnh Ninh
A17: 14 | B17: Bảng sạc pin | C17: 1 | G17: 3200000 | H17: combo 5 bảng+tiền tk+VAT+ ship | I17: Nguyễn Thành
A18: 15 | B18: Mạch test dung lượng + trở sứ | C18: 25 | G18: 812500 | H18: SHOPEE (xem trong nhóm)
A19: 16 | B19: Mạch test dung lượng + trở sứ | C19: 20 | G19: 653000 | H19: SHOPEE (xem trong nhóm)
A20: 17 | B20: Máy mài MKT TQ | C20: 1 | G20: 350000 | H20: xe Thanh đem về
A21: 18 | B21: Khoan 3CN starker 10mm đỏ | C21: 1 | G21: 260000 | H21: xe Thanh đem về
A22: 19 | B22: Bulong mkt TQ xám | C22: 1 | G22: 240000 | H22: xe Thanh đem về
A23: 20 | B23: Vít 173 tq xanh | C23: 1 | G23: 420000 | H23: xe Thanh đem về
A24: 21 | B24: Khoan 13mm YMS xanh | C24: 1 | G24: 800000 | H24: xe Thanh đem về
A25: 22 | B25: Đèn led nhỏ | C25: 1 | G25: 100000 | H25: xe Thanh đem về
A26: 23 | B26: Quạt lồg sắt | C26: 1 | G26: 115000 | H26: xe Thanh đem về
A27: 24 | B27: Kích điện từ pin lên 220v | C27: 1 | G27: 250000 | H27: xe Thanh đem về
B28: Thiếc hàng nhật 800g 0.8mm | C28: 1 | D28: 580000 | G28: 580000 | H28: xe Thanh đem về | I28: Hiếu LK
A29: 25 | B29: Bộ hộp pin xe điện (có khung+kẽm) | C29: 1 | G29: 160000 | H29: gửi xe Thanh chuyển xe bà Hà | I29: Tuấn Mạnh AZ
A30: 26 | B30: Mạch pin 13/14s 40A | C30: 1 | G30: 160000 | H30: gửi xe Thanh chuyển xe bà Hà
A31: 27 | B31: Sạc 2s2A rẻ | C31: 2 | D31: 30000 | G31: =C31*D31 -> 60000 | H31: gửi xe Thanh chuyển xe bà Hà
A32: 28 | B32: sạc 3s2A rẻ | C32: 2 | D32: 30000 | G32: =C32*D32 -> 60000 | H32: gửi xe Thanh chuyển xe bà Hà
A33: 29 | B33: Sạc 3s2A thường | C33: 2 | D33: 55000 | G33: =C33*D33 -> 110000 | H33: gửi xe Thanh chuyển xe bà Hà
A34: 30 | B34: Sạc 4s2A thường | C34: 2 | D34: 55000 | G34: =C34*D34 -> 110000 | H34: gửi xe Thanh chuyển xe bà Hà
B35: Sạc 5s2A rẻ | C35: 2 | D35: 30000 | G35: =C35*D35 -> 60000 | H35: gửi xe Thanh chuyển xe bà Hà
B36: Sạc 5s2A thường | C36: 2 | D36: 55000 | G36: =C36*D36 -> 110000 | H36: gửi xe Thanh chuyển xe bà Hà
B37: Sạc 5s3A có quạt | C37: 2 | D37: 110000 | G37: =C37*D37 -> 220000 | H37: gửi xe Thanh chuyển xe bà Hà
B38: Jack Xt60 | C38: 4 | D38: 3500 | G38: =C38*D38 -> 14000 | H38: gửi xe Thanh chuyển xe bà Hà
B39: Đèn NLMT BC 200w | C39: 1 | G39: 700000 | H39: gửi xe Thanh chuyển xe bà Hà
B40: Đèn NLMT pha 300w | C40: 1 | G40: 950000 | H40: gửi xe Thanh chuyển xe bà Hà
...

Sheet Tiền chuyển cho long
A1: Từ đầu đến ngày 2/3/2026 tc ck cho long là50tr | C1: 45 000 000

Sheet Đơn trả lại
A1: NHỮNG ĐƠN HÀNG TRẢ LẠI CHO LONG
A3: STT | B3: TÊN ĐƠN HÀNG | C3: Loại | D3: SỐ LƯỢNG | E3: THÀNH TIỀN
A4: 1 | B4: A123 | D4: 50 | E4: 1150000
A5: 2 | B5: MÁY MÀI MKT TQ | D5: 1 | E5: 350000
A6: 3 | B6: PIN21700 | D6: 5V
A7: 4 | B7: FIN18600 | D7: 6V

Sheet Đơn hàng đã bán
A1: ĐƠN HÀNG ĐÃ BÁN CHO KHÁCH | G1: Sđt | H1: Ngày mua
I2: Số điện thoại
A3: TÊN FB | B3: SẢN PHẨM | C3: SỐ ĐIỆN THOẠI | D3: SỐ TIỀN | E3: TRẢ | F3: CÒN | G3: Chú thích | J3: Tổng tiền: | K3: =SUM(D4:D20001) -> 34640000
A4: TÂM LÊ | B4: 1FIN 12AH | C4: 935694536 | D4: 1200000 | E4: 1200000 | F4: =D4-E4 -> 0 | J4: Tổng đã thu: | K4: =SUM(E4:E20001) -> 26150000
A5: KHOÁ NGUYỄN | B5: 1SAC1FIN7,5AH | C5: 983926939 | D5: 950000 | E5: 950000 | F5: =D5-E5 -> 0 | G5: Mạch+đóng | J5: Nợ còn: | K5: =SUM(F4:F20001) -> 7890000
A6: HUỲNH KIỀU | B6: 1 ĐÈN NL 300W | C6: 377732140 | D6: 1200000 | E6: 1200000 | F6: =D6-E6 -> 0
A7: NGUYỄN PHƯỚC THIỆN | B7: 1 SẠC DỰ PHÒNG 4CELL | C7: 364909695 | D7: 550000 | E7: 550000 | F7: =D7-E7 -> 0
A8: HÀ LÊ | B8: 1BINH XE MÁY | C8: 987475125 | D8: 600000 | E8: 600000 | F8: =D8-E8 -> 0
A9: Bình lâm Tâm | B9: Bình 30a | C9: 972947410 | F9: =D9-E9 -> 0
A10: Vĩnh bộ đội | B10: Bình 45A | D10: 2300000 | E10: 1700000
A11: Vương | B11: Pin 15cell | D11: 700000 | E11: 700000 | F11: =D11-E11 -> 0
A12: Sang | B12: Pin15cell-sạc-đèn | D12: 1000000 | E12: 1000000 | F12: =D12-E12 -> 0
A13: Liên cơ khí | B13: Đèn | D13: 250000 | E13: 250000 | F13: =D13-E13 -> 0
A14: Anh Hiệp | B14: Camera -pin5cell-đèn,sạc | D14: 650000 | E14: 650000 | F14: =D14-E14 -> 0
A15: Vĩnh bộ đội | B15: Bình 45ah-pin15cell-máy vít -sạc | D15: 3830000 | E15: 1600000 | F15: =D15-E15 -> 2230000
A16: Ut chup,0375064153/12/1/2026 | B16: Bình 45ah | D16: 2250000 | E16: 2250000 | F16: =D16-E16 -> 0 | G16: 375064152 | H16: 46034
A17: Bi trương | B17: Sạc tốt 5a | D17: 150000 | E17: 150000 | F17: =D17-E17 -> 0 | H17: 46039
A18: Phế liệu qs | B18: Pin15cell,máy bu lông | D18: 1500000 | E18: 1500000 | F18: =D18-E18 -> 0 | H18: 46045
A19: Phế liệu qs | B19: Pin 15cell1máy cắt,sạc | D19: 1300000 | E19: 1300000 | F19: =D19-E19 -> 0 | H19: 37/1/2026
A20: Tiên đoan | B20: Pin10-15cell,sạc | D20: 1350000 | E20: 1350000 | F20: =D20-E20 -> 0 | H20: 28/012026
A21: Khoá | B21: Sạc dự phòng | D21: 600000 | F21: =D21-E21 -> 600000 | H21: 46048
A22: Phế liệu qs | B22: Pin15cell,1 máy buloong | D22: 1200000 | E22: 1200000 | F22: =D22-E22 -> 0 | H22: 46084
A23: Mẹ Thêu QM | B23: Đèn NL đĩa bay | D23: 1500000 | E23: 1500000 | F23: =D23-E23 -> 0 | H23: 46088
A24: Khoá | B24: Thay mạch 4s | D24: 80000 | F24: =D24-E24 -> 80000 | H24: 46101
A25: Khoá | B25: 2 pin 15cell+1 sạch nhanh | D25: 1650000 | F25: =D25-E25 -> 1650000 | H25: 46104
A26: Long rèn | B26: Pin áo | D26: 550000 | E26: 550000 | H26: 46114
A27: Quốc dinh | B27: Pin áo,sạc | D27: 700000 | E27: 700000 | F27: =D27-E27 -> 0 | H27: 46116 | I27: 086 9029139
A28: Đội 6 thôn 2 | B28: Đèn năng lượng | D28: 1300000 | E28: 1300000 | F28: =D28-E28 -> 0 | H28: 46119
A29: Thủy hoa t4 | B29: Pin áo 6cell217 | D29: 600000 | F29: =D29-E29 -> 600000 | H29: 46122
A30: Vợ thày đ15 | B30: Đèn NL,mã | D30: 1250000 | E30: 1250000 | F30: =D30-E30 -> 0 | H30: 46121 | I30: 039 7504447
A31: Khoá | B31: Sạc 16,8v | D31: 70000 | F31: =D31-E31 -> 70000 | H31: 46130
A32: Quốc đ15 | B32: Pin áo điều hòa | D32: 470000 | E32: 470000 | F32: =D32-E32 -> 0 | H32: 46130
A33: Vinh bé sâm | B33: Pin áo điều hòa | D33: 600000 | E33: 600000 | F33: =D33-E33 -> 0 | H33: 46132
A34: Kha đ9 | B34: Pin áo điều hòa | D34: 480000 | E34: 480000 | F34: =D34-E34 -> 0 | H34: 46134
A35: Ngọc t1 | B35: Pin áo điều hoà | D35: 600000 | F35: =D35-E35 -> 600000 | H35: 46136
A36: Lê Tâm | B36: Pin 20cell | D36: 1150000 | E36: 1150000 | F36: =D36-E36 -> 0 | H36: 46146
A37: Nguyễn phước Thiện | B37: Bình 12v30ah+quạt 12v | D37: 2060000 | F37: =D37-E37 -> 2060000 | H37: 46147
A38: Tuấn công an | B38: 1pin 15cell1 xạc | F38: =D38-E38 -> 0
A39: Chính xe | B39: 1 pin 15cell | F39: =D39-E39 -> 0
A40: Ánh đội 15 | B40: 1 pin 16v | F40: =D40-E40 -> 0
...
